Workbook

Sheet Summary
A1: LPMS - Test Case Execution Summary
A2: Change the Status dropdown on the 'Test Cases' sheet; counts below update automatically.
A4: Status | B4: Count | C4: % of Total
A5: Pass | B5: =COUNTIF('Test Cases'!$H$2:$H$88,A5) -> 37 | C5: =IFERROR(B5/$B$10,0) -> 0.42528736
A6: Fail | B6: =COUNTIF('Test Cases'!$H$2:$H$88,A6) -> 0 | C6: =IFERROR(B6/$B$10,0) -> 0
A7: Blocked | B7: =COUNTIF('Test Cases'!$H$2:$H$88,A7) -> 0 | C7: =IFERROR(B7/$B$10,0) -> 0
A8: Not Run | B8: =COUNTIF('Test Cases'!$H$2:$H$88,A8) -> 29 | C8: =IFERROR(B8/$B$10,0) -> 0.33333333
A9: Not Implemented | B9: =COUNTIF('Test Cases'!$H$2:$H$88,A9) -> 21 | C9: =IFERROR(B9/$B$10,0) -> 0.24137931
A10: Total | B10: =SUM(B5:B9) -> 87 | C10: =SUM(C5:C9) -> 1
A12: Module | B12: Total | C12: Pass | D12: Pass %
A13: Auth | B13: =COUNTIF('Test Cases'!$B$2:$B$88,A13) -> 3 | C13: =COUNTIFS('Test Cases'!$B$2:$B$88,A13,'Test Cases'!$H$2:$H$88,"Pass") -> 0 | D13: =IFERROR(C13/B13,0) -> 0
A14: Employee | B14: =COUNTIF('Test Cases'!$B$2:$B$88,A14) -> 13 | C14: =COUNTIFS('Test Cases'!$B$2:$B$88,A14,'Test Cases'!$H$2:$H$88,"Pass") -> 5 | D14: =IFERROR(C14/B14,0) -> 0.38461538
A15: Leave | B15: =COUNTIF('Test Cases'!$B$2:$B$88,A15) -> 14 | C15: =COUNTIFS('Test Cases'!$B$2:$B$88,A15,'Test Cases'!$H$2:$H$88,"Pass") -> 4 | D15: =IFERROR(C15/B15,0) -> 0.28571429
A16: Attendance | B16: =COUNTIF('Test Cases'!$B$2:$B$88,A16) -> 25 | C16: =COUNTIFS('Test Cases'!$B$2:$B$88,A16,'Test Cases'!$H$2:$H$88,"Pass") -> 17 | D16: =IFERROR(C16/B16,0) -> 0.68
A17: Payroll | B17: =COUNTIF('Test Cases'!$B$2:$B$88,A17) -> 24 | C17: =COUNTIFS('Test Cases'!$B$2:$B$88,A17,'Test Cases'!$H$2:$H$88,"Pass") -> 3 | D17: =IFERROR(C17/B17,0) -> 0.125
A18: Security | B18: =COUNTIF('Test Cases'!$B$2:$B$88,A18) -> 8 | C18: =COUNTIFS('Test Cases'!$B$2:$B$88,A18,'Test Cases'!$H$2:$H$88,"Pass") -> 8 | D18: =IFERROR(C18/B18,0) -> 1
A20: Notes
A21: Status as of 19-Oct-2026 (project LPMS_v5 + Stage 6 work in progress).
A22: 'Pass' on UT-xx rows = verified by running the JUnit suite in this session: 37 tests, 37 passed, 0 failed.
A23: Manual rows are 'Not Run' - nobody has executed them yet; set Pass/Fail yourself after testing against a running app + MySQL.
A24: PAY-xx rows and TC-PAY-004 are Stage 6 (payroll engine) - 'Not Implemented' until the stage is finished and tested.
A25: Source of manual cases: docs/test-cases.md in the project ZIP (some earlier 'Passed' marks there were for unit tests only).

Sheet Test Cases
A1: Test ID | B1: Module | C1: Requirement | D1: Test Scenario | E1: Expected Result | F1: Type | G1: Automated Test (class#method) | H1: Status | I1: Verification Evidence | J1: Tester | K1: Date Tested | L1: Remarks
A2: TC-AUTH-001 | B2: Auth | C2: FR-AUTH-001 | D2: Valid login credentials | E2: Access granted, session created, redirect to dashboard | F2: Manual | H2: Not Run | I2: Not verified
A3: TC-AUTH-002 | B3: Auth | C3: FR-AUTH-001 | D3: Invalid password | E3: Access denied, 'Invalid username/password' shown | F3: Manual | H3: Not Run | I3: Not verified
A4: TC-AUTH-003 | B4: Auth | C4: NFR-SEC-001 | D4: Session timeout after 30 mins | E4: Session invalidated, re-login forced | F4: Manual | H4: Not Run | I4: Not verified
A5: TC-EMP-001 | B5: Employee | C5: FR-EMP-001 | D5: Add new employee (HR_ADMIN only) | E5: Record created in database | F5: Manual | H5: Not Run | I5: Not verified
A6: TC-EMP-002 | B6: Employee | C6: FR-EMP-001 | D6: Add employee with invalid email/phone/DOB | E6: 400 with specific validation message, nothing saved | F6: Manual | H6: Not Run | I6: Not verified
A7: TC-EMP-003 | B7: Employee | C7: FR-EMP-002 | D7: HR edits department, manager, phone | E7: Row updated, audit_log UPDATE entry written | F7: Manual | H7: Not Run | I7: Not verified
A8: TC-EMP-004 | B8: Employee | C8: FR-EMP-002 | D8: Set reporting manager that creates a loop | E8: 400 'reporting loop'; no change | F8: Manual | H8: Not Run | I8: Not verified
A9: TC-EMP-005 | B9: Employee | C9: FR-EMP-003 | D9: Search by name/ID/email, filter by dept/status | E9: Only matching rows; Manager sees only reports | F9: Manual | H9: Not Run | I9: Not verified
A10: TC-EMP-006 | B10: Employee | C10: FR-EMP-004 | D10: Deactivate employee | E10: is_active false, status RESIGNED/TERMINATED, exit date set | F10: Manual | H10: Not Run | I10: Not verified
A11: TC-EMP-007 | B11: Employee | C11: FR-EMP-004 | D11: Delete employee with attendance/leave history | E11: 409, record kept; delete only when no history | F11: Manual | H11: Not Run | I11: Not verified
A12: TC-EMP-008 | B12: Employee | C12: NFR-SEC-002 | D12: MANAGER/EMPLOYEE call POST/PUT/DELETE employees | E12: 403 Forbidden | F12: Manual | H12: Not Run | I12: Not verified
A13: TC-LEAVE-001 | B13: Leave | C13: FR-LEAVE-001 | D13: Apply leave (Start <= End) | E13: Submitted, status PENDING | F13: Manual | H13: Not Run | I13: Not verified
... A30: ATT-07 | B30: Attendance | C30: Stage 5 | D30: Change policy MISSING_DAY_TREATMENT=IGNORE | E30: Summary LOP updates | F30: Manual | H30: Not Run | I30: Not verified
A31: UT-01 | B31: Security | C31: Unit | D31: Payroll/reference paths are HR-only | E31: Test passes | F31: Automated (JUnit) | G31: RoleRulesTest#payrollAndReferenceAreHrOnly | H31: Pass | I31: Verified: JUnit run, 37/37 passed
A32: UT-02 | B32: Security | C32: Unit | D32: Manager paths allow manager and HR | E32: Test passes | F32: Automated (JUnit) | G32: RoleRulesTest#managerPathsAllowManagerAndHr | H32: Pass | I32: Verified: JUnit run, 37/37 passed
A33: UT-03 | B33: Security | C33: Unit | D33: Self-service paths open to all roles | E33: Test passes | F33: Automated (JUnit) | G33: RoleRulesTest#selfServicePathsOpenToAll | H33: Pass | I33: Verified: JUnit run, 37/37 passed
A34: UT-04 | B34: Payroll | C34: Unit | D34: Flat component returns exact amount (TC-PAY-001) | E34: Test passes | F34: Automated (JUnit) | G34: PayrollRuleEngineTest#testCalculateFlatComponent | H34: Pass | I34: Verified: JUnit run, 37/37 passed
A35: UT-05 | B35: Payroll | C35: Unit | D35: Percentage component of gross (TC-PAY-002) | E35: Test passes | F35: Automated (JUnit) | G35: PayrollRuleEngineTest#testCalculatePercentageComponent | H35: Pass | I35: Verified: JUnit run, 37/37 passed
A36: UT-06 | B36: Payroll | C36: Unit | D36: LOP deduction by LOP days (TC-PAY-003) | E36: Test passes | F36: Automated (JUnit) | G36: PayrollRuleEngineTest#testCalculateLopDeduction | H36: Pass | I36: Verified: JUnit run, 37/37 passed
A37: UT-07 | B37: Attendance | C37: Unit | D37: Defaults used when nothing stored | E37: Test passes | F37: Automated (JUnit) | G37: AttendancePolicyTest#defaultsApplyWhenNothingStored | H37: Pass | I37: Verified: JUnit run, 37/37 passed
A38: UT-08 | B38: Attendance | C38: Unit | D38: Policy keys/values validated | E38: Test passes | F38: Automated (JUnit) | G38: AttendancePolicyTest#validatesKeysAndValues | H38: Pass | I38: Verified: JUnit run, 37/37 passed
A39: UT-09 | B39: Attendance | C39: Unit | D39: Invalid stored values fall back | E39: Test passes | F39: Automated (JUnit) | G39: AttendancePolicyTest#invalidStoredValuesFallBackToDefaults | H39: Pass | I39: Verified: JUnit run, 37/37 passed
A40: UT-10 | B40: Attendance | C40: Unit | D40: Full attendance -> no LOP | E40: Test passes | F40: Automated (JUnit) | G40: AttendanceRulesTest#fullAttendanceHasNoLop | H40: Pass | I40: Verified: JUnit run, 37/37 passed
A41: UT-11 | B41: Attendance | C41: Unit | D41: Holidays excluded from working days | E41: Test passes | F41: Automated (JUnit) | G41: AttendanceRulesTest#holidaysAreNotWorkingDays | H41: Pass | I41: Verified: JUnit run, 37/37 passed
A42: UT-12 | B42: Attendance | C42: Unit | D42: Absent/missing days are LOP | E42: Test passes | F42: Automated (JUnit) | G42: AttendanceRulesTest#absentAndMissingDaysAreLop | H42: Pass | I42: Verified: JUnit run, 37/37 passed
... A67: UT-37 | B67: Security | C67: Unit | D67: Session stamp changes with hash | E67: Test passes | F67: Automated (JUnit) | G67: SecurityUtilTest#stampChangesWithHash | H67: Pass | I67: Verified: JUnit run, 37/37 passed
A68: TC-PAY-004 | B68: Payroll | C68: FR-PAY-002 | D68: Run monthly payroll batch | E68: employee_payroll + payroll_item rows generated | F68: Manual | H68: Not Implemented | I68: Stage 6 in progress - not yet integrated/tested | L68: Old servlet was a mock; real engine being built
A69: PAY-01 | B69: Payroll | C69: Stage 6 | D69: Gross = sum of configured earnings (Basic + allowances) | E69: Gross matches component sum, 2-decimal rounding | F69: Manual | H69: Not Implemented | I69: Stage 6 in progress - not verified
A70: PAY-02 | B70: Payroll | C70: Stage 6 | D70: Percentage components use monthly gross; flat use exact value | E70: Amounts correct, HALF_UP rounding | F70: Manual | H70: Not Implemented | I70: Stage 6 in progress - not verified
A71: PAY-03 | B71: Payroll | C71: Stage 6 | D71: LOP deduction = gross x LOP days / basis days (working/calendar) | E71: Single rounding, capped at gross | F71: Manual | H71: Not Implemented | I71: Stage 6 in progress - not verified
A72: PAY-04 | B72: Payroll | C72: Stage 6 | D72: Attendance LOP days read from MySQL feed payroll | E72: LOP matches attendance summary | F72: Manual | H72: Not Implemented | I72: Stage 6 in progress - not verified
A73: PAY-05 | B73: Payroll | C73: Stage 6 | D73: Mid-month joiner/leaver paid only for employed days | E73: Extra LOP for non-employed working days | F73: Manual | H73: Not Implemented | I73: Stage 6 in progress - not verified
A74: PAY-06 | B74: Payroll | C74: Stage 6 | D74: PF % applies to PF-applicable earnings, optional wage ceiling | E74: PF capped when ceiling set | F74: Manual | H74: Not Implemented | I74: Stage 6 in progress - not verified
A75: PAY-07 | B75: Payroll | C75: Stage 6 | D75: Employer contribution stored but not deducted from net | E75: Net unaffected | F75: Manual | H75: Not Implemented | I75: Stage 6 in progress - not verified
A76: PAY-08 | B76: Payroll | C76: Stage 6 | D76: Tax disabled (default) / no slabs configured | E76: Tax = 0 with warning, no invented rates | F76: Manual | H76: Not Implemented | I76: Stage 6 in progress - not verified
A77: PAY-09 | B77: Payroll | C77: Stage 6 | D77: Tax enabled with configured slabs, cess, std deduction, rebate | E77: Progressive tax /12 per month | F77: Manual | H77: Not Implemented | I77: Stage 6 in progress - not verified
A78: PAY-10 | B78: Payroll | C78: Stage 6 | D78: Net = Gross - (LOP + deductions) | E78: Total deductions and net correct | F78: Manual | H78: Not Implemented | I78: Stage 6 in progress - not verified
A79: PAY-11 | B79: Payroll | C79: Stage 6 | D79: Negative net / negative component / percentage >100 / zero gross | E79: Employee skipped with reason; no bad data saved | F79: Manual | H79: Not Implemented | I79: Stage 6 in progress - not verified
A80: PAY-12 | B80: Payroll | C80: Stage 6 | D80: Employee without active salary structure | E80: Skipped and reported | F80: Manual | H80: Not Implemented | I80: Stage 6 in progress - not verified
...
